[2024-11-14T16:56:38.087+0000] {local_task_job_runner.py:120} INFO - ::group::Pre task execution logs
[2024-11-14T16:56:38.111+0000] {taskinstance.py:2076} INFO - Dependencies all met for dep_context=non-requeueable deps ti=<TaskInstance: Stock_DAG_ELT_dbt.dbt_run manual__2024-11-14T16:56:37.230437+00:00 [queued]>
[2024-11-14T16:56:38.118+0000] {taskinstance.py:2076} INFO - Dependencies all met for dep_context=requeueable deps ti=<TaskInstance: Stock_DAG_ELT_dbt.dbt_run manual__2024-11-14T16:56:37.230437+00:00 [queued]>
[2024-11-14T16:56:38.119+0000] {taskinstance.py:2306} INFO - Starting attempt 1 of 1
[2024-11-14T16:56:38.130+0000] {taskinstance.py:2330} INFO - Executing <Task(BashOperator): dbt_run> on 2024-11-14 16:56:37.230437+00:00
[2024-11-14T16:56:38.135+0000] {standard_task_runner.py:90} INFO - Running: ['***', 'tasks', 'run', 'Stock_DAG_ELT_dbt', 'dbt_run', 'manual__2024-11-14T16:56:37.230437+00:00', '--job-id', '74', '--raw', '--subdir', 'DAGS_FOLDER/Stock_DAG_ELT.py', '--cfg-path', '/tmp/tmp9g5kyj9d']
[2024-11-14T16:56:38.137+0000] {standard_task_runner.py:91} INFO - Job 74: Subtask dbt_run
[2024-11-14T16:56:38.138+0000] {logging_mixin.py:188} WARNING - /home/***/.local/lib/python3.12/site-packages/***/task/task_runner/standard_task_runner.py:61 DeprecationWarning: This process (pid=471) is multi-threaded, use of fork() may lead to deadlocks in the child.
[2024-11-14T16:56:38.138+0000] {standard_task_runner.py:63} INFO - Started process 472 to run task
[2024-11-14T16:56:38.172+0000] {task_command.py:426} INFO - Running <TaskInstance: Stock_DAG_ELT_dbt.dbt_run manual__2024-11-14T16:56:37.230437+00:00 [running]> on host 773bdfe74e06
[2024-11-14T16:56:38.250+0000] {taskinstance.py:2648} INFO - Exporting env vars: AIRFLOW_CTX_DAG_OWNER='***' AIRFLOW_CTX_DAG_ID='Stock_DAG_ELT_dbt' AIRFLOW_CTX_TASK_ID='dbt_run' AIRFLOW_CTX_EXECUTION_DATE='2024-11-14T16:56:37.230437+00:00' AIRFLOW_CTX_TRY_NUMBER='1' AIRFLOW_CTX_DAG_RUN_ID='manual__2024-11-14T16:56:37.230437+00:00'
[2024-11-14T16:56:38.251+0000] {taskinstance.py:430} INFO - ::endgroup::
[2024-11-14T16:56:38.263+0000] {subprocess.py:63} INFO - Tmp dir root location: /tmp
[2024-11-14T16:56:38.264+0000] {subprocess.py:75} INFO - Running command: ['/usr/bin/bash', '-c', '/home/***/.local/bin/dbt run --profiles-dir /opt/***/dbt_lab2 --project-dir /opt/***/dbt_lab2']
[2024-11-14T16:56:38.271+0000] {subprocess.py:86} INFO - Output:
[2024-11-14T16:56:39.996+0000] {subprocess.py:93} INFO - [0m16:56:39  Running with dbt=1.8.7
[2024-11-14T16:56:39.997+0000] {subprocess.py:93} INFO - [0m16:56:39  Encountered an error:
[2024-11-14T16:56:39.997+0000] {subprocess.py:93} INFO - Runtime Error
[2024-11-14T16:56:39.998+0000] {subprocess.py:93} INFO -   No dbt_project.yml found at expected path /opt/***/dbt_lab2/dbt_project.yml
[2024-11-14T16:56:39.998+0000] {subprocess.py:93} INFO -   Verify that each entry within packages.yml (and their transitive dependencies) contains a file named dbt_project.yml
[2024-11-14T16:56:39.998+0000] {subprocess.py:93} INFO - 
[2024-11-14T16:56:40.721+0000] {subprocess.py:97} INFO - Command exited with return code 2
[2024-11-14T16:56:40.722+0000] {taskinstance.py:441} INFO - ::group::Post task execution logs
[2024-11-14T16:56:40.731+0000] {taskinstance.py:2905} ERROR - Task failed with exception
Traceback (most recent call last):
  File "/home/airflow/.local/lib/python3.12/site-packages/airflow/models/taskinstance.py", line 465, in _execute_task
    result = _execute_callable(context=context, **execute_callable_kwargs)
             ^^^^^^^^^^^^^^^^^^^^^^^^^^^^^^^^^^^^^^^^^^^^^^^^^^^^^^^^^^^^^
  File "/home/airflow/.local/lib/python3.12/site-packages/airflow/models/taskinstance.py", line 432, in _execute_callable
    return execute_callable(context=context, **execute_callable_kwargs)
           ^^^^^^^^^^^^^^^^^^^^^^^^^^^^^^^^^^^^^^^^^^^^^^^^^^^^^^^^^^^^
  File "/home/airflow/.local/lib/python3.12/site-packages/airflow/models/baseoperator.py", line 400, in wrapper
    return func(self, *args, **kwargs)
           ^^^^^^^^^^^^^^^^^^^^^^^^^^^
  File "/home/airflow/.local/lib/python3.12/site-packages/airflow/operators/bash.py", line 243, in execute
    raise AirflowException(
airflow.exceptions.AirflowException: Bash command failed. The command returned a non-zero exit code 2.
[2024-11-14T16:56:40.734+0000] {taskinstance.py:1206} INFO - Marking task as FAILED. dag_id=Stock_DAG_ELT_dbt, task_id=dbt_run, run_id=manual__2024-11-14T16:56:37.230437+00:00, execution_date=20241114T165637, start_date=20241114T165638, end_date=20241114T165640
[2024-11-14T16:56:40.748+0000] {standard_task_runner.py:110} ERROR - Failed to execute job 74 for task dbt_run (Bash command failed. The command returned a non-zero exit code 2.; 472)
[2024-11-14T16:56:40.762+0000] {local_task_job_runner.py:240} INFO - Task exited with return code 1
[2024-11-14T16:56:40.779+0000] {taskinstance.py:3498} INFO - 0 downstream tasks scheduled from follow-on schedule check
[2024-11-14T16:56:40.783+0000] {local_task_job_runner.py:222} INFO - ::endgroup::
